---
layout: post
title: try-catch详解
description: 对try-catch语句的详细描述，来自阮一峰的书<a href="http://javascript.ruanyifeng.com/grammar/error.html">《Javascript标准参考教程alpha》</a>
keywords: Frank,try-catch
---

##try-catch结构

>为了对错误进行处理，需要使用try...catch结构。

{% highlight javascript %}
try {
  throw new Error('出错了!');
} catch (e) {
  console.log(e.name + ": " + e.message);  // Error: 出错了！
  console.log(e.stack);  // 不是标准属性，但是浏览器支持
}
// Error: 出错了!
// Error: 出错了!
//   at <anonymous>:3:9
//   at Object.InjectedScript._evaluateOn (<anonymous>:895:140)
//   at Object.InjectedScript._evaluateAndWrap (<anonymous>:828:34)
//   at Object.InjectedScript.evaluate (<anonymous>:694:21)

{% endhighlight %}

>上面代码中，`try`代码块抛出的错误（包括用`throw`语句抛出错误），可以被`catch`代码块捕获。`catch`接受一个参数，表示`try`代码块传入的错误对象。

{% highlight js %}

function throwIt(exception) {
  try {
    throw exception;
  } catch (e) {
    console.log('Caught: '+e);
  }
}

throwIt(3);
// Caught: 3
throwIt('hello');
// Caught: hello
throwIt(new Error('An error happened'));
// Caught: Error: An error happened

{% endhighlight %}

>`catch`代码块捕获错误之后，程序不会中断，会按照正常流程继续执行下去。

{% highlight js %}
try {
  throw "出错了";
} catch (e) {
  console.log(111);
}
console.log(222);
// 111
// 222
{% endhighlight %}

>上面代码中，try代码块抛出的错误，被catch代码块捕获后，程序会继续向下执行。
catch代码块之中，还可以再抛出错误，甚至使用嵌套的try...catch结构。

{% highlight js %}
try {
   throw n; // 这里抛出一个整数
} catch (e) {
   if (e <= 50) {
      // 针对1-50的错误的处理
   } else {
      // 大于50的错误无法处理，再抛出一个错误
      throw e;
   }
}
{% endhighlight %}

>为了捕捉不同类型的错误，catch代码块之中可以加入判断语句。

{% highlight js %}
try {
  foo.bar();
} catch (e) {
  if (e instanceof EvalError) {
    console.log(e.name + ": " + e.message);
  } else if (e instanceof RangeError) {
    console.log(e.name + ": " + e.message);
  }
  // ... 
}
{% endhighlight %}

>try...catch结构是JavaScript语言受到Java语言影响的一个明显的例子。这种结构多多少少是对结构化编程原则一种破坏，处理不当就会变成类似goto语句的效果，应该谨慎使用。

##finally代码块

>try...catch结构允许在最后添加一个finally代码块，表示不管是否出现错误，都必需在最后运行的语句。

{% highlight js %}
function cleansUp() {
    try {
        throw new Error('Sorry...');
    } finally {
        console.log('Performing clean-up');
    }
}

cleansUp()
// Performing clean-up
// Error: Sorry...
{% endhighlight %}

>上面代码说明，throw语句抛出错误以后，finanlly继续得到执行。

{% highlight js %}
function idle(x) {
    try {
        console.log(x);
        return 'result';
    } finally {
        console.log("FINALLY");
    }
}

idle('hello')
// hello
// FINALLY
// "result"
{% endhighlight %}

>上面代码说明，即使有return语句在前，finally代码块依然会得到执行，且在其执行完毕后，才会显示return语句的值。

下面的例子说明，return语句的执行是排在finanlly代码之前，只是等finnally代码执行完毕后才返回。

{% highlight js %}
var count = 0;
function countUp() {
    try {
        return count;
    } finally {
        count++;
    }
}

countUp()
// 0
count
// 1
{% endhighlight %}

>上面代码说明，return语句的count的值，是在finally代码块运行之前，就获取完成了。

下面是另一个例子。
{% highlight js %}
openFile();

try {
   writeFile(Data);
} catch(e) {
    handleError(e);
} finally {
   closeFile();
}
{% endhighlight %}

>上面代码首先打开一个文件，然后在try代码块中写入文件，如果没有发生错误，则运行finally代码块关闭文件；一旦发生错误，则先使用catch代码块处理错误，再使用finally代码块关闭文件。

下面的例子充分反应了try...catch...finally这三者之间的执行顺序。

{% highlight js %}
function f() {
    try {
        console.log(0);
        throw "bug";
    } catch(e) {
        console.log(1);
        return true; // 这句会延迟到finally代码块结束再执行
        console.log(2); // 不会运行
    } finally {
        console.log(3);
        return false; // 这句会覆盖掉前面那句return
        console.log(4); // 不会运行
    }
    
    console.log(5); // 不会运行
}

var result = f(); 
// 0
// 1
// 3

result
// false
{% endhighlight %}

>某些情况下，甚至可以省略catch代码块，只使用finally代码块。
{% highlight js %}
openFile();

try {
   writeFile(Data);
} finally {
   closeFile();
}
{% endhighlight %}


